<?xml version="1.0" ?>
<!-- =================================================================================== -->
<!-- |    This document was autogenerated by xacro from 6dof_manipulator.xacro         | -->
<!-- |    EDITING THIS FILE BY HAND IS NOT RECOMMENDED                                 | -->
<!-- =================================================================================== -->
<robot name="manipulator">
  <material name="white">
    <color rgba="1.0 1.0 1.0 1.000"/>
  </material>

  <gazebo reference="base_link">
    <material>Gazebo/White</material>
  </gazebo>
  <gazebo reference="link_1_1">
    <material>Gazebo/White</material>
  </gazebo>
  <gazebo reference="link_2_1">
    <material>Gazebo/White</material>
  </gazebo>
  <gazebo reference="link_3_1">
    <material>Gazebo/White</material>
  </gazebo>
  <gazebo reference="link_4_1">
    <material>Gazebo/White</material>
  </gazebo>
  <gazebo reference="link_5_1">
    <material>Gazebo/White</material>
  </gazebo>
  <gazebo reference="link_6_1">
    <material>Gazebo/White</material>
  </gazebo>
  <link name="world"></link>
  <joint name="base_joint" type="fixed">
    <origin rpy="0 0 0" xyz="0.0 0.0 0.0"/>
    <parent link="world"/>
    <child link="base_link"/>
  </joint>
  <link name="base_link">
    <inertial>
      <origin xyz="-7.295026833610489e-13 0.00010550764230433382 0.0246125319938844" rpy="0 0 0"/>
      <mass value="2.1649980446638213"/>
      <inertia ixx="0.004793" iyy="0.004798" izz="0.007227" ixy="0.0" iyz="2e-06" ixz="-0.0"/>
    </inertial>
    <visual>
      <origin xyz="0 0 0" rpy="0 0 0"/>
      <geometry>
        <mesh filename="package://manipulator_6dof_description/meshes/base_link.stl" scale="0.001 0.001 0.001"/>
      </geometry>
      <material name="white"/>
    </visual>
    <collision>
      <origin xyz="0 0 0" rpy="0 0 0"/>
      <geometry>
        <mesh filename="package://manipulator_6dof_description/meshes/base_link.stl" scale="0.001 0.001 0.001"/>
      </geometry>
    </collision>
  </link>

  <link name="link_1_1">
    <inertial>
      <origin xyz="0.003470462191355766 0.00013682029127464138 0.028443076641690046" rpy="0 0 0"/>
      <mass value="1.044429977886197"/>
      <inertia ixx="0.000963" iyy="0.00091" izz="0.000689" ixy="-0.0" iyz="-2e-06" ixz="-5.1e-05"/>
    </inertial>
    <visual>
      <origin xyz="-0.0 0.0 -0.062" rpy="0 0 0"/>
      <geometry>
        <mesh filename="package://manipulator_6dof_description/meshes/link_1_1.stl" scale="0.001 0.001 0.001"/>
      </geometry>
      <material name="white"/>
    </visual>
    <collision>
      <origin xyz="-0.0 0.0 -0.062" rpy="0 0 0"/>
      <geometry>
        <mesh filename="package://manipulator_6dof_description/meshes/link_1_1.stl" scale="0.001 0.001 0.001"/>
      </geometry>
    </collision>
  </link>

  <link name="link_2_1">
    <inertial>
      <origin xyz="-0.026722953125703865 0.00013326397239950415 0.06739644020751422" rpy="0 0 0"/>
      <mass value="1.0723019224070052"/>
      <inertia ixx="0.002051" iyy="0.001984" izz="0.000559" ixy="0.0" iyz="-3e-06" ixz="0.000178"/>
    </inertial>
    <visual>
      <origin xyz="0.025 -0.0002 -0.116" rpy="0 0 0"/>
      <geometry>
        <mesh filename="package://manipulator_6dof_description/meshes/link_2_1.stl" scale="0.001 0.001 0.001"/>
      </geometry>
      <material name="white"/>
    </visual>
    <collision>
      <origin xyz="0.025 -0.0002 -0.116" rpy="0 0 0"/>
      <geometry>
        <mesh filename="package://manipulator_6dof_description/meshes/link_2_1.stl" scale="0.001 0.001 0.001"/>
      </geometry>
    </collision>
  </link>

  <link name="link_3_1">
    <inertial>
      <origin xyz="0.0312627075493882 1.3193656236976103e-15 0.03703539841440315" rpy="0 0 0"/>
      <mass value="0.8938660668299434"/>
      <inertia ixx="0.000796" iyy="0.000904" izz="0.000594" ixy="0.0" iyz="0.0" ixz="-0.000128"/>
    </inertial>
    <visual>
      <origin xyz="0.025 -0.0004 -0.221" rpy="0 0 0"/>
      <geometry>
        <mesh filename="package://manipulator_6dof_description/meshes/link_3_1.stl" scale="0.001 0.001 0.001"/>
      </geometry>
      <material name="white"/>
    </visual>
    <collision>
      <origin xyz="0.025 -0.0004 -0.221" rpy="0 0 0"/>
      <geometry>
        <mesh filename="package://manipulator_6dof_description/meshes/link_3_1.stl" scale="0.001 0.001 0.001"/>
      </geometry>
    </collision>
  </link>

  <link name="link_4_1">
    <inertial>
      <origin xyz="-0.004361142167998326 3.1864701849348975e-16 0.033501841180729575" rpy="0 0 0"/>
      <mass value="0.8311251067189291"/>
      <inertia ixx="0.000659" iyy="0.000604" izz="0.000381" ixy="0.0" iyz="-0.0" ixz="2.9e-05"/>
    </inertial>
    <visual>
      <origin xyz="0.0 -0.0004 -0.301" rpy="0 0 0"/>
      <geometry>
        <mesh filename="package://manipulator_6dof_description/meshes/link_4_1.stl" scale="0.001 0.001 0.001"/>
      </geometry>
      <material name="white"/>
    </visual>
    <collision>
      <origin xyz="0.0 -0.0004 -0.301" rpy="0 0 0"/>
      <geometry>
        <mesh filename="package://manipulator_6dof_description/meshes/link_4_1.stl" scale="0.001 0.001 0.001"/>
      </geometry>
    </collision>
  </link>

  <link name="link_5_1">
    <inertial>
      <origin xyz="-0.012340892698794424 0.00015120168831259242 0.05231129430932063" rpy="0 0 0"/>
      <mass value="0.8431959857300293"/>
      <inertia ixx="0.000683" iyy="0.000786" izz="0.000514" ixy="0.0" iyz="-1e-06" ixz="8.4e-05"/>
    </inertial>
    <visual>
      <origin xyz="-0.025 -0.0004 -0.354" rpy="0 0 0"/>
      <geometry>
        <mesh filename="package://manipulator_6dof_description/meshes/link_5_1.stl" scale="0.001 0.001 0.001"/>
      </geometry>
      <material name="white"/>
    </visual>
    <collision>
      <origin xyz="-0.025 -0.0004 -0.354" rpy="0 0 0"/>
      <geometry>
        <mesh filename="package://manipulator_6dof_description/meshes/link_5_1.stl" scale="0.001 0.001 0.001"/>
      </geometry>
    </collision>
  </link>

  <link name="link_6_1">
    <inertial>
      <origin xyz="-1.5272053280057805e-14 1.3695641842836892e-15 0.0038944720792071785" rpy="0 0 0"/>
      <mass value="0.08319729963947381"/>
      <inertia ixx="1.4e-05" iyy="1.5e-05" izz="2.5e-05" ixy="-0.0" iyz="0.0" ixz="-0.0"/>
    </inertial>
    <visual>
      <origin xyz="0.0 -0.0006 -0.447" rpy="0 0 0"/>
      <geometry>
        <mesh filename="package://manipulator_6dof_description/meshes/link_6_1.stl" scale="0.001 0.001 0.001"/>
      </geometry>
      <material name="white"/>
    </visual>
    <collision>
      <origin xyz="0.0 -0.0006 -0.447" rpy="0 0 0"/>
      <geometry>
        <mesh filename="package://manipulator_6dof_description/meshes/link_6_1.stl" scale="0.001 0.001 0.001"/>
      </geometry>
    </collision>
  </link>

  <joint name="revolute1" type="revolute">
    <origin xyz="0.0 0.0 0.062" rpy="0 0 0"/>
    <parent link="base_link"/>
    <child link="link_1_1"/>
    <axis xyz="0.0 0.0 1.0"/>
    <limit effort="10" lower="-3.14" upper="3.14" velocity="20.0" />
  </joint>

  <joint name="revolute2" type="revolute">
    <origin xyz="-0.025 0.0002 0.054" rpy="0 0 0"/>
    <parent link="link_1_1"/>
    <child link="link_2_1"/>
    <axis xyz="1.0 0.0 0.0"/>
    <limit effort="10" lower="-3.14" upper="3.14" velocity="20.0" />
  </joint>

  <joint name="revolute3" type="revolute">
    <origin xyz="0.0 0.0002 0.105" rpy="0 0 0"/>
    <parent link="link_2_1"/>
    <child link="link_3_1"/>
    <axis xyz="1.0 -0.0 0.0"/>
    <limit effort="10" lower="-3.14" upper="3.14" velocity="20.0" />
  </joint>

  <joint name="revolute4" type="revolute">
    <origin xyz="0.025 0.0 0.08" rpy="0 0 0"/>
    <parent link="link_3_1"/>
    <child link="link_4_1"/>
    <axis xyz="-0.0 0.0 1.0"/>
    <limit effort="10" lower="-3.14" upper="3.14" velocity="20.0" />
  </joint>

  <joint name="revolute5" type="revolute">
    <origin xyz="0.025 0.0 0.053" rpy="0 0 0"/>
    <parent link="link_4_1"/>
    <child link="link_5_1"/>
    <axis xyz="1.0 0.0 0.0"/>
    <limit effort="10" lower="-3.14" upper="3.14" velocity="20.0" />
  </joint>

  <joint name="revolute6" type="revolute">
    <origin xyz="-0.025 0.0002 0.093" rpy="0 0 0"/>
    <parent link="link_5_1"/>
    <child link="link_6_1"/>
    <axis xyz="-0.0 -0.0 1.0"/>
    <limit effort="10" lower="-3.14" upper="3.14" velocity="20.0" />
  </joint>
</robot>
