<?xml version="1.0" ?>
<!-- =================================================================================== -->
<!-- |    This document was autogenerated by xacro from 6dof_manipulator.xacro         | -->
<!-- |    EDITING THIS FILE BY HAND IS NOT RECOMMENDED                                 | -->
<!-- =================================================================================== -->
<robot name="manipulator">
  <material name="silver">
    <color rgba="0.700 0.700 0.700 1.000"/>
  </material>

  <gazebo reference="base_link">
    <material>Gazebo/Silver</material>
  </gazebo>
  <gazebo reference="link_1_1">
    <material>Gazebo/Silver</material>
  </gazebo>
  <gazebo reference="link_2_1">
    <material>Gazebo/Silver</material>
  </gazebo>
  <gazebo reference="link_3_1">
    <material>Gazebo/Silver</material>
  </gazebo>
  <gazebo reference="link_4_1">
    <material>Gazebo/Silver</material>
  </gazebo>
  <gazebo reference="link_5_1">
    <material>Gazebo/Silver</material>
  </gazebo>
  <gazebo reference="link_6_1">
    <material>Gazebo/Silver</material>
  </gazebo>
  <link name="world"></link>
  <joint name="base_joint" type="fixed">
    <origin rpy="0 0 0" xyz="0.0 0.0 0.0"/>
    <parent link="world"/>
    <child link="base_link"/>
  </joint>
  <link name="base_link">
    <inertial>
      <origin rpy="0 0 0" xyz="-1.1580046200244058e-17 5.790023100122029e-18 0.024999999999999994"/>
      <mass value="3.082687791334984"/>
      <inertia ixx="0.002569" ixy="-0.0" ixz="-0.0" iyy="0.002569" iyz="-0.0" izz="0.003853"/>
    </inertial>
    <visual>
      <origin rpy="0 0 0" xyz="0 0 0"/>
      <geometry>
        <mesh filename="package://manipulator_6dof_description/meshes/base_link.stl" scale="0.001 0.001 0.001"/>
      </geometry>
      <material name="silver"/>
    </visual>
    <collision>
      <origin rpy="0 0 0" xyz="0 0 0"/>
      <geometry>
        <mesh filename="package://manipulator_6dof_description/meshes/base_link.stl" scale="0.001 0.001 0.001"/>
      </geometry>
    </collision>
  </link>
  <link name="link_1">
    <inertial>
      <origin rpy="0 0 0" xyz="0.0 -5.1115539124864905e-18 0.061962398667886"/>
      <mass value="3.491860562928356"/>
      <inertia ixx="0.005515" ixy="0.0" ixz="0.0" iyy="0.005565" iyz="-0.0" izz="0.002045"/>
    </inertial>
    <visual>
      <origin rpy="0 0 0" xyz="-0.0 -0.0 -0.05"/>
      <geometry>
        <mesh filename="package://manipulator_6dof_description/meshes/link_1.stl" scale="0.001 0.001 0.001"/>
      </geometry>
      <material name="silver"/>
    </visual>
    <collision>
      <origin rpy="0 0 0" xyz="-0.0 -0.0 -0.05"/>
      <geometry>
        <mesh filename="package://manipulator_6dof_description/meshes/link_1.stl" scale="0.001 0.001 0.001"/>
      </geometry>
    </collision>
  </link>
  <link name="link_2">
    <inertial>
      <origin rpy="0 0 0" xyz="-0.03 0.09999999999999995 -2.7755575615628914e-17"/>
      <mass value="6.983721125856714"/>
      <inertia ixx="0.037843" ixy="0.0" ixz="0.0" iyy="0.00409" iyz="-0.0" izz="0.037943"/>
    </inertial>
    <visual>
      <origin rpy="0 0 0" xyz="0.03 -0.0 -0.15"/>
      <geometry>
        <mesh filename="package://manipulator_6dof_description/meshes/link_2.stl" scale="0.001 0.001 0.001"/>
      </geometry>
      <material name="silver"/>
    </visual>
    <collision>
      <origin rpy="0 0 0" xyz="0.03 -0.0 -0.15"/>
      <geometry>
        <mesh filename="package://manipulator_6dof_description/meshes/link_2.stl" scale="0.001 0.001 0.001"/>
      </geometry>
    </collision>
  </link>
  <link name="link_3">
    <inertial>
      <origin rpy="0 0 0" xyz="0.03 0.03803760133211398 2.7755575615628914e-17"/>
      <mass value="3.491860562928356"/>
      <inertia ixx="0.005515" ixy="-0.0" ixz="-0.0" iyy="0.002045" iyz="-0.0" izz="0.005565"/>
    </inertial>
    <visual>
      <origin rpy="0 0 0" xyz="0.03 -0.2 -0.15"/>
      <geometry>
        <mesh filename="package://manipulator_6dof_description/meshes/link_3.stl" scale="0.001 0.001 0.001"/>
      </geometry>
      <material name="silver"/>
    </visual>
    <collision>
      <origin rpy="0 0 0" xyz="0.03 -0.2 -0.15"/>
      <geometry>
        <mesh filename="package://manipulator_6dof_description/meshes/link_3.stl" scale="0.001 0.001 0.001"/>
      </geometry>
    </collision>
  </link>
  <link name="link_4">
    <inertial>
      <origin rpy="0 0 0" xyz="0.006088612846208392 0.021359696326836708 2.7755575615628914e-17"/>
      <mass value="1.0936161975597023"/>
      <inertia ixx="0.000722" ixy="-0.000191" ixz="0.0" iyy="0.000887" iyz="0.0" izz="0.000869"/>
    </inertial>
    <visual>
      <origin rpy="0 0 0" xyz="-0.0 -0.3 -0.15"/>
      <geometry>
        <mesh filename="package://manipulator_6dof_description/meshes/link_4.stl" scale="0.001 0.001 0.001"/>
      </geometry>
      <material name="silver"/>
    </visual>
    <collision>
      <origin rpy="0 0 0" xyz="-0.0 -0.3 -0.15"/>
      <geometry>
        <mesh filename="package://manipulator_6dof_description/meshes/link_4.stl" scale="0.001 0.001 0.001"/>
      </geometry>
    </collision>
  </link>
  <link name="link_5">
    <inertial>
      <origin rpy="0 0 0" xyz="-0.030000000000000013 0.012914286065527247 0.0"/>
      <mass value="2.0788605629283565"/>
      <inertia ixx="0.001554" ixy="0.0" ixz="0.0" iyy="0.001197" iyz="0.0" izz="0.001604"/>
    </inertial>
    <visual>
      <origin rpy="0 0 0" xyz="-0.025 -0.35 -0.15"/>
      <geometry>
        <mesh filename="package://manipulator_6dof_description/meshes/link_5.stl" scale="0.001 0.001 0.001"/>
      </geometry>
      <material name="silver"/>
    </visual>
    <collision>
      <origin rpy="0 0 0" xyz="-0.025 -0.35 -0.15"/>
      <geometry>
        <mesh filename="package://manipulator_6dof_description/meshes/link_5.stl" scale="0.001 0.001 0.001"/>
      </geometry>
    </collision>
  </link>
  <link name="link_6">
    <inertial>
      <origin rpy="0 0 0" xyz="-1.734723475976807e-17 0.027445769703058065 2.7755575615628914e-17"/>
      <mass value="1.4877079110604057"/>
      <inertia ixx="0.000902" ixy="-0.0" ixz="-0.0" iyy="0.00085" iyz="0.0" izz="0.000902"/>
    </inertial>
    <visual>
      <origin rpy="0 0 0" xyz="0.005 -0.4 -0.15"/>
      <geometry>
        <mesh filename="package://manipulator_6dof_description/meshes/link_6.stl" scale="0.001 0.001 0.001"/>
      </geometry>
      <material name="silver"/>
    </visual>
    <collision>
      <origin rpy="0 0 0" xyz="0.005 -0.4 -0.15"/>
      <geometry>
        <mesh filename="package://manipulator_6dof_description/meshes/link_6.stl" scale="0.001 0.001 0.001"/>
      </geometry>
    </collision>
  </link>
  <joint name="revolute1" type="revolute">
    <origin rpy="0 0 0" xyz="0.0 0.0 0.05"/>
    <parent link="base_link"/>
    <child link="link_1"/>
    <axis xyz="0.0 0.0 1.0"/>
    <limit effort="10" lower="-3.14" upper="3.14" velocity="20.0" />
  </joint>
  <joint name="revolute2" type="revolute">
    <origin rpy="0 0 0" xyz="-0.03 0.0 0.1"/>
    <parent link="link_1"/>
    <child link="link_2"/>
    <axis xyz="1.0 0.0 0.0"/>
    <limit effort="10" lower="-3.14" upper="3.14" velocity="20.0" />
  </joint>
  <joint name="revolute3" type="revolute">
    <origin rpy="0 0 0" xyz="0.0 0.2 0.0"/>
    <parent link="link_2"/>
    <child link="link_3"/>
    <axis xyz="1.0 0.0 0.0"/>
    <limit effort="10" lower="-3.14" upper="3.14" velocity="20.0" />
  </joint>
  <joint name="revolute4" type="revolute">
    <origin rpy="0 0 0" xyz="0.03 0.1 0.0"/>
    <parent link="link_3"/>
    <child link="link_4"/>
    <axis xyz="0.0 1.0 0.0"/>
    <limit effort="10" lower="-3.14" upper="3.14" velocity="20.0" />
  </joint>
  <joint name="revolute5" type="revolute">
    <origin rpy="0 0 0" xyz="0.025 0.05 0.0"/>
    <parent link="link_4"/>
    <child link="link_5"/>
    <axis xyz="1.0 0.0 0.0"/>
    <limit effort="10" lower="-3.14" upper="3.14" velocity="20.0" />
  </joint>
  <joint name="revolute6" type="revolute">
    <origin rpy="0 0 0" xyz="-0.03 0.05 0.0"/>
    <parent link="link_5"/>
    <child link="link_6"/>
    <axis xyz="0.0 1.0 0.0"/>
    <limit effort="10" lower="-3.14" upper="3.14" velocity="20.0" />
  </joint>
</robot>
